2025-09-25 08:41:07 +0000 - dagster - DEBUG - daily_pipeline - 187a44dc-1808-4ae3-91d8-dc8d095e3636 - 11118 - LOGS_CAPTURED - Started capturing logs in process (pid: 11118).
2025-09-25 08:41:07 +0000 - dagster - DEBUG - daily_pipeline - 187a44dc-1808-4ae3-91d8-dc8d095e3636 - 11118 - export_csv_snapshot - STEP_START - Started execution of step "export_csv_snapshot".
2025-09-25 08:41:08 +0000 - dagster - ERROR - daily_pipeline - 187a44dc-1808-4ae3-91d8-dc8d095e3636 - 11118 - export_csv_snapshot - STEP_FAILURE - Execution of step "export_csv_snapshot" failed.

dagster._core.errors.DagsterExecutionStepExecutionError: Error occurred while executing op "export_csv_snapshot"::

duckdb.duckdb.CatalogException: Catalog Error: Table with name daily_snapshot does not exist!
Did you mean "main_marts.daily_snapshot"?
LINE 1: COPY (select * from marts.daily_snapshot) TO '/app/data/exp...
                            ^

Stack Trace:
  File "/usr/local/lib/python3.11/site-packages/dagster/_core/execution/plan/utils.py", line 54, in op_execution_error_boundary
    yield
  File "/usr/local/lib/python3.11/site-packages/dagster/_utils/__init__.py", line 474, in iterate_with_context
    next_output = next(iterator)
                  ^^^^^^^^^^^^^^
  File "/usr/local/lib/python3.11/site-packages/dagster/_core/execution/plan/compute_generator.py", line 141, in _coerce_op_compute_fn_to_iterator
    result = invoke_compute_fn(
             ^^^^^^^^^^^^^^^^^^
  File "/usr/local/lib/python3.11/site-packages/dagster/_core/execution/plan/compute_generator.py", line 129, in invoke_compute_fn
    return fn(context, **args_to_pass) if context_arg_provided else fn(**args_to_pass)
                                                                    ^^^^^^^^^^^^^^^^^^
  File "/app/orchestration/dagster_project/src/assets_export_csv.py", line 32, in export_csv_snapshot
    con.execute(f"COPY (select * from {TABLE}) TO '{csv_path.as_posix()}' WITH (HEADER, DELIMITER ',')")

