2025-09-25 07:07:30 +0000 - dagster - DEBUG - daily_pipeline - 48333f01-7233-4a4c-9ddb-974a92885cc8 - 2512 - LOGS_CAPTURED - Started capturing logs in process (pid: 2512).
2025-09-25 07:07:30 +0000 - dagster - DEBUG - daily_pipeline - 48333f01-7233-4a4c-9ddb-974a92885cc8 - 2512 - dbt_build_models - STEP_START - Started execution of step "dbt_build_models".
2025-09-25 07:07:54 +0000 - dagster - ERROR - daily_pipeline - 48333f01-7233-4a4c-9ddb-974a92885cc8 - 2512 - dbt_build_models - STEP_FAILURE - Execution of step "dbt_build_models" failed.

dagster._core.errors.DagsterExecutionStepExecutionError: Error occurred while executing op "dbt_build_models"::

RuntimeError

Stack Trace:
  File "/usr/local/lib/python3.11/site-packages/dagster/_core/execution/plan/utils.py", line 54, in op_execution_error_boundary
    yield
  File "/usr/local/lib/python3.11/site-packages/dagster/_utils/__init__.py", line 473, in iterate_with_context
    next_output = next(iterator)
                  ^^^^^^^^^^^^^^
  File "/usr/local/lib/python3.11/site-packages/dagster/_core/execution/plan/compute_generator.py", line 141, in _coerce_op_compute_fn_to_iterator
    result = invoke_compute_fn(
             ^^^^^^^^^^^^^^^^^^
  File "/usr/local/lib/python3.11/site-packages/dagster/_core/execution/plan/compute_generator.py", line 129, in invoke_compute_fn
    return fn(context, **args_to_pass) if context_arg_provided else fn(**args_to_pass)
                                                                    ^^^^^^^^^^^^^^^^^^
  File "/app/orchestration/dagster_project/src/assets_transform_dbt.py", line 15, in dbt_build_models
    raise RuntimeError(out.stderr)

